Start training...
Traceback (most recent call last):
  File "/itet-stor/taosun47/net_scratch/anaconda3/envs/py37-torch/lib/python3.7/runpy.py", line 193, in _run_module_as_main
    "__main__", mod_spec)
  File "/itet-stor/taosun47/net_scratch/anaconda3/envs/py37-torch/lib/python3.7/runpy.py", line 85, in _run_code
    exec(code, run_globals)
  File "/home/taosun47/Working/vis4d/vis4d/op/segment/fcn_voc_training.py", line 225, in <module>
    ckpt_dir=ckpt_dir
  File "/home/taosun47/Working/vis4d/vis4d/op/segment/fcn_voc_training.py", line 107, in training_loop
    losses = model(image.to(device), target.to(device))
  File "/itet-stor/taosun47/net_scratch/anaconda3/envs/py37-torch/lib/python3.7/site-packages/torch/nn/modules/module.py", line 1130, in _call_impl
    return forward_call(*input, **kwargs)
  File "/home/taosun47/Working/vis4d/vis4d/op/segment/fcn_voc_training.py", line 50, in forward
    outputs = self.fcn(features)
  File "/home/taosun47/Working/vis4d/vis4d/op/segment/base.py", line 28, in __call__
    return super()._call_impl(x)
  File "/itet-stor/taosun47/net_scratch/anaconda3/envs/py37-torch/lib/python3.7/site-packages/torch/nn/modules/module.py", line 1130, in _call_impl
    return forward_call(*input, **kwargs)
  File "/home/taosun47/Working/vis4d/vis4d/op/segment/fcn.py", line 214, in forward
    outputs[idx] = F.softmax(output, diim=1)
TypeError: softmax() got an unexpected keyword argument 'diim'
